<?xml version="1.0"?>
<sdf version="1.10">
    <world name="car_world">
        <physics name="1ms" type="ignored">
            <max_step_size>0.001</max_step_size>
            <real_time_factor>1.0</real_time_factor>
        </physics>
        <plugin
            filename="gz-sim-physics-system"
            name="gz::sim::systems::Physics">
        </plugin>
        <plugin
            filename="gz-sim-user-commands-system"
            name="gz::sim::systems::UserCommands">
        </plugin>
        <plugin
            filename="gz-sim-scene-broadcaster-system"
            name="gz::sim::systems::SceneBroadcaster">
        </plugin>
        <plugin filename="gz-sim-sensors-system"
            name="gz::sim::systems::Sensors">
            <render_engine>ogre2</render_engine>
        </plugin>
        <plugin filename="gz-sim-imu-system"
            name="gz::sim::systems::Imu">
        </plugin>
        <plugin filename="gz-sim-contact-system"
            name="gz::sim::systems::Contact">
        </plugin>

        <light type="directional" name="sun">
            <cast_shadows>true</cast_shadows>
            <pose>0 0 10 0 0 0</pose>
            <diffuse>0.8 0.8 0.8 1</diffuse>
            <specular>0.2 0.2 0.2 1</specular>
            <attenuation>
                <range>1000</range>
                <constant>0.9</constant>
                <linear>0.01</linear>
                <quadratic>0.001</quadratic>
            </attenuation>
            <direction>-0.5 0.1 -0.9</direction>
        </light>

        <model name="ground_plane">
            <static>true</static>
            <link name="link">
                <collision name="collision">
                    <geometry>
                        <plane>
                            <normal>0 0 1</normal>
                        </plane>
                    </geometry>
                </collision>
                <visual name="visual">
                    <geometry>
                        <plane>
                            <normal>0 0 1</normal>
                            <size>100 100</size>
                        </plane>
                    </geometry>
                    <material>
                        <ambient>0.8 0.8 0.8 1</ambient>
                        <diffuse>0.8 0.8 0.8 1</diffuse>
                        <specular>0.8 0.8 0.8 1</specular>
                    </material>
                </visual>
            </link>
        </model>

        <model name='vehicle_blue' canonical_link='chassis'>
            <pose relative_to='world'>0 0 0 0 0 0</pose>

            <!-- Chassis-->
            <link name='chassis'>
                <pose relative_to='__model__'>0.5 0 0.4 0 0 0</pose>
                <inertial>
                    <mass>1.14395</mass>
                    <inertia>
                        <ixx>0.095329</ixx>
                        <ixy>0</ixy>
                        <ixz>0</ixz>
                        <iyy>0.381317</iyy>
                        <iyz>0</iyz>
                        <izz>0.476646</izz>
                    </inertia>
                </inertial>
                <visual name='visual'>
                    <geometry>
                        <box>
                            <size>2.0 1.0 0.5</size>
                        </box>
                    </geometry>
                    <material>
                        <ambient>0.42 0.42 0.42 1</ambient>
                        <diffuse>0.42 0.42 0.42 1</diffuse>
                        <specular>0.42 0.42 0.42 1</specular>
                    </material>
                </visual>
                <collision name='collision'>
                    <geometry>
                        <box>
                            <size>2.0 1.0 0.5</size>
                        </box>
                    </geometry>
                </collision>
                <sensor name="imu_sensor" type="imu">
                    <always_on>1</always_on>
                    <update_rate>1</update_rate>
                    <visualize>true</visualize>
                    <topic>imu</topic>
                </sensor>
            </link>

            <!-- Left Rear Wheel-->
            <link name='left_rear_wheel'>
                <pose relative_to='chassis'>-0.5 0.6 0 -1.5707 0 0</pose>
                <inertial>
                    <mass>1</mass>
                    <inertia>
                        <ixx>0.043333</ixx>
                        <ixy>0</ixy>
                        <ixz>0</ixz>
                        <iyy>0.043333</iyy>
                        <iyz>0</iyz>
                        <izz>0.08</izz>
                    </inertia>
                </inertial>
                <visual name='visual'>
                    <geometry>
                        <cylinder>
                            <radius>0.4</radius>
                            <length>0.2</length>
                        </cylinder>
                    </geometry>
                    <material>
                        <ambient>0.161 0.161 0.161 1</ambient>
                        <diffuse>0.161 0.161 0.161 1</diffuse>
                        <specular>0.161 0.161 0.161 1</specular>
                    </material>
                </visual>
                <collision name='collision'>
                    <geometry>
                        <cylinder>
                            <radius>0.4</radius>
                            <length>0.2</length>
                        </cylinder>
                    </geometry>
                </collision>
            </link>

            <!-- Right Rear Wheel-->
            <link name='right_rear_wheel'>
                <pose relative_to='chassis'>-0.5 -0.6 0 -1.5707 0 0</pose>
                <inertial>
                    <mass>1</mass>
                    <inertia>
                        <ixx>0.043333</ixx>
                        <ixy>0</ixy>
                        <ixz>0</ixz>
                        <iyy>0.043333</iyy>
                        <iyz>0</iyz>
                        <izz>0.08</izz>
                    </inertia>
                </inertial>
                <visual name='visual'>
                    <geometry>
                        <cylinder>
                            <radius>0.4</radius>
                            <length>0.2</length>
                        </cylinder>
                    </geometry>
                    <material>
                        <ambient>0.161 0.161 0.161 1</ambient>
                        <diffuse>0.161 0.161 0.161 1</diffuse>
                        <specular>0.161 0.161 0.161 1</specular>
                    </material>
                </visual>
                <collision name='collision'>
                    <geometry>
                        <cylinder>
                            <radius>0.4</radius>
                            <length>0.2</length>
                        </cylinder>
                    </geometry>
                </collision>
            </link>

            <!-- Left Front Wheel-->
            <link name='left_front_wheel'>
                <pose relative_to='chassis'>0.5 0.6 0 -1.5707 0 0</pose>
                <inertial>
                    <mass>1</mass>
                    <inertia>
                        <ixx>0.043333</ixx>
                        <ixy>0</ixy>
                        <ixz>0</ixz>
                        <iyy>0.043333</iyy>
                        <iyz>0</iyz>
                        <izz>0.08</izz>
                    </inertia>
                </inertial>
                <visual name='visual'>
                    <geometry>
                        <cylinder>
                            <radius>0.4</radius>
                            <length>0.2</length>
                        </cylinder>
                    </geometry>
                    <material>
                        <ambient>0.161 0.161 0.161 1</ambient>
                        <diffuse>0.161 0.161 0.161 1</diffuse>
                        <specular>0.161 0.161 0.161 1</specular>
                    </material>
                </visual>
                <collision name='collision'>
                    <geometry>
                        <cylinder>
                            <radius>0.4</radius>
                            <length>0.2</length>
                        </cylinder>
                    </geometry>
                </collision>
            </link>

            <!-- Right Front Wheel-->
            <link name='right_front_wheel'>
                <pose relative_to='chassis'>0.5 -0.6 0 -1.5707 0 0</pose>
                <inertial>
                    <mass>1</mass>
                    <inertia>
                        <ixx>0.043333</ixx>
                        <ixy>0</ixy>
                        <ixz>0</ixz>
                        <iyy>0.043333</iyy>
                        <iyz>0</iyz>
                        <izz>0.08</izz>
                    </inertia>
                </inertial>
                <visual name='visual'>
                    <geometry>
                        <cylinder>
                            <radius>0.4</radius>
                            <length>0.2</length>
                        </cylinder>
                    </geometry>
                    <material>
                        <ambient>0.161 0.161 0.161 1</ambient>
                        <diffuse>0.161 0.161 0.161 1</diffuse>
                        <specular>0.161 0.161 0.161 1</specular>
                    </material>
                </visual>
                <collision name='collision'>
                    <geometry>
                        <cylinder>
                            <radius>0.4</radius>
                            <length>0.2</length>
                        </cylinder>
                    </geometry>
                </collision>
            </link>

            <!-- Left Rear Wheel Joint-->
            <joint name='left_rear_wheel_joint' type='revolute'>
                <pose relative_to='left_rear_wheel' />
                <parent>chassis</parent>
                <child>left_rear_wheel</child>
                <axis>
                    <xyz expressed_in='__model__'>0 1 0</xyz>
                    <limit>
                        <!-- negative infinity-->
                        <lower>-1.79769e+308</lower>
                        <!-- positive infinity-->
                        <upper>1.79769e+308</upper>
                    </limit>
                </axis>
            </joint>

            <!-- Right Rear Wheel Joint-->
            <joint name='right_rear_wheel_joint' type='revolute'>
                <pose relative_to='right_rear_wheel' />
                <parent>chassis</parent>
                <child>right_rear_wheel</child>
                <axis>
                    <xyz expressed_in='__model__'>0 1 0</xyz>
                    <limit>
                        <!-- negative infinity-->
                        <lower>-1.79769e+308</lower>
                        <!-- positive infinity-->
                        <upper>1.79769e+308</upper>
                    </limit>
                </axis>
            </joint>

            <!-- Left Front Wheel Joint-->
            <joint name='left_front_wheel_joint' type='revolute'>
                <pose relative_to='left_front_wheel' />
                <parent>chassis</parent>
                <child>left_front_wheel</child>
                <axis>
                    <xyz expressed_in='__model__'>0 1 0</xyz>
                    <limit>
                        <!-- negative infinity-->
                        <lower>-1.79769e+308</lower>
                        <!-- positive infinity-->
                        <upper>1.79769e+308</upper>
                    </limit>
                </axis>
            </joint>

            <!-- RIght Front Wheel Joint-->
            <joint name='right_front_wheel_joint' type='revolute'>
                <pose relative_to='right_front_wheel' />
                <parent>chassis</parent>
                <child>right_front_wheel</child>
                <axis>
                    <xyz expressed_in='__model__'>0 1 0</xyz>
                    <limit>
                        <!-- negative infinity-->
                        <lower>-1.79769e+308</lower>
                        <!-- positive infinity-->
                        <upper>1.79769e+308</upper>
                    </limit>
                </axis>
            </joint>

            <!-- Differential Drive Plugin-->
            <plugin filename="gz-sim-diff-drive-system"
                name="gz::sim::systems::DiffDrive">
                <left_joint>left_front_wheel_joint</left_joint>
                <left_joint>left_rear_wheel_joint</left_joint>
                <right_joint>right_front_wheel_joint</right_joint>
                <right_joint>right_rear_wheel_joint</right_joint>
                <wheel_separation>1.2</wheel_separation>
                <wheel_radius>0.4</wheel_radius>
                <odom_publish_frequency>1</odom_publish_frequency>
                <topic>cmd_vel</topic>
            </plugin>

            <!-- Lidar-->
            <link name='lidar_link'>
                <pose relative_to='chassis'>0.8 0 0.5 0 0 0</pose>
                <inertial>
                    <mass>0.1</mass>
                    <inertia>
                        <ixx>0.000166667</ixx>
                        <iyy>0.000166667</iyy>
                        <izz>0.000166667</izz>
                    </inertia>
                </inertial>
                <visual name='visual'>
                    <geometry>
                        <cylinder>
                            <radius>0.05</radius>
                            <length>0.1</length>
                        </cylinder>
                    </geometry>
                </visual>
                <sensor name='gpu_lidar' type='gpu_lidar'>
                    <topic>lidar</topic>
                    <update_rate>10</update_rate>
                    <lidar>
                        <scan>
                            <horizontal>
                                <samples>640</samples>
                                <resolution>1</resolution>
                                <min_angle>-1.396263</min_angle>
                                <max_angle>1.396263</max_angle>
                            </horizontal>
                        </scan>
                        <range>
                            <min>0.08</min>
                            <max>10.0</max>
                        </range>
                    </lidar>
                    <visualize>true</visualize>
                </sensor>
            </link>

            <!-- Lidar Joint-->
            <joint name='lidar_joint' type='fixed'>
                <parent>chassis</parent>
                <child>lidar_link</child>
            </joint>
        </model>

        <!-- Wall-->
        <model name='wall'>
            <static>true</static>
            <pose>10 0 0 0 0 0</pose>
            <link name='box'>
                <visual name='visual'>
                    <geometry>
                        <box>
                            <size>0.5 10.0 2.0</size>
                        </box>
                    </geometry>
                    <material>
                        <ambient>0.0 0.0 1.0 1</ambient>
                        <diffuse>0.0 0.0 1.0 1</diffuse>
                        <specular>0.0 0.0 1.0 1</specular>
                    </material>
                </visual>
                <collision name='collision'>
                    <geometry>
                        <box>
                            <size>0.5 10.0 2.0</size>
                        </box>
                    </geometry>
                </collision>
                <sensor name='sensor_contact' type='contact'>
                    <contact>
                        <collision>collision</collision>
                    </contact>
                </sensor>
            </link>
            <plugin filename="gz-sim-touchplugin-system"
                name="gz::sim::systems::TouchPlugin">
                <target>vehicle_blue</target>
                <namespace>wall</namespace>
                <time>0.001</time>
                <enabled>true</enabled>
            </plugin>
        </model>

        <!-- Box -->
        <model name='box'>
            <static>true</static>
            <pose>7 7 0.5 0 0 0</pose>
            <link name='box'>
                <visual name='visual'>
                    <geometry>
                        <box>
                            <size>2 2 2</size>
                        </box>
                    </geometry>
                    <material>
                        <ambient>0.7 0.5 0.9 1</ambient>
                        <diffuse>0.7 0.5 0.9 1</diffuse>
                        <specular>0.7 0.5 0.9 1</specular>
                    </material>
                </visual>
                <collision name='collision'>
                    <geometry>
                        <box>
                            <size>2 2 2</size>
                        </box>
                    </geometry>
                </collision>
                <sensor name='sensor_contact' type='contact'>
                    <contact>
                        <collision>collision</collision>
                    </contact>
                </sensor>
            </link>
            <plugin filename="gz-sim-touchplugin-system"
                name="gz::sim::systems::TouchPlugin">
                <target>vehicle_blue</target>
                <namespace>wall</namespace>
                <time>0.001</time>
                <enabled>true</enabled>
            </plugin>
        </model>

        <!-- Barrel -->
        <model name='barrel'>
            <static>true</static>
            <pose>8 -5 1 0 0 0</pose>
            <link name='box'>
                <visual name='visual'>
                    <geometry>
                        <cylinder>
                            <radius>0.7</radius>
                            <length>2</length>
                        </cylinder>
                    </geometry>
                    <material>
                        <ambient>0.2 0.5 0.9 1</ambient>
                        <diffuse>0.2 0.5 0.9 1</diffuse>
                        <specular>0.2 0.5 0.9 1</specular>
                    </material>
                </visual>
                <collision name='collision'>
                    <geometry>
                        <cylinder>
                            <radius>0.7</radius>
                            <length>2</length>
                        </cylinder>
                    </geometry>
                </collision>
                <sensor name='sensor_contact' type='contact'>
                    <contact>
                        <collision>collision</collision>
                    </contact>
                </sensor>
            </link>
            <plugin filename="gz-sim-touchplugin-system"
                name="gz::sim::systems::TouchPlugin">
                <target>vehicle_blue</target>
                <namespace>wall</namespace>
                <time>0.001</time>
                <enabled>true</enabled>
            </plugin>
        </model>

        <!-- Moving Forward-->
        <plugin filename="gz-sim-triggered-publisher-system"
            name="gz::sim::systems::TriggeredPublisher">
            <input type="gz.msgs.Int32" topic="/keyboard/keypress">
                <match field="data">16777235</match>
            </input>
            <output type="gz.msgs.Twist" topic="/cmd_vel">
                linear: {x: 0.5}, angular: {z: 0.0}
            </output>
        </plugin>

        <!-- Moving Backward-->
        <plugin filename="gz-sim-triggered-publisher-system"
            name="gz::sim::systems::TriggeredPublisher">
            <input type="gz.msgs.Int32" topic="/keyboard/keypress">
                <match field="data">16777237</match>
            </input>
            <output type="gz.msgs.Twist" topic="/cmd_vel">
                linear: {x: -0.5}, angular: {z: 0.0}
            </output>
        </plugin>

        <!-- Moving Left-->
        <plugin filename="gz-sim-triggered-publisher-system"
            name="gz::sim::systems::TriggeredPublisher">
            <input type="gz.msgs.Int32" topic="/keyboard/keypress">
                <match field="data">16777234</match>
            </input>
            <output type="gz.msgs.Twist" topic="/cmd_vel">
                linear: {x: 0.0}, angular: {z: 0.5}
            </output>
        </plugin>

        <!-- Moving Right-->
        <plugin filename="gz-sim-triggered-publisher-system"
            name="gz::sim::systems::TriggeredPublisher">
            <input type="gz.msgs.Int32" topic="/keyboard/keypress">
                <match field="data">16777236</match>
            </input>
            <output type="gz.msgs.Twist" topic="/cmd_vel">
                linear: {x: 0.0}, angular: {z: -0.5}
            </output>
        </plugin>

        <!-- Stop When Hit The Wall-->
        <plugin filename="gz-sim-triggered-publisher-system"
            name="gz::sim::systems::TriggeredPublisher">
            <input type="gz.msgs.Boolean" topic="/wall/touched">
                <match>data: true</match>
            </input>
            <output type="gz.msgs.Twist" topic="/cmd_vel">
                linear: {x: 0.0}, angular: {z: 0.0}
            </output>
        </plugin>
    </world>
</sdf>