<?xml version="1.0"?>
<!--
  Simple differential drive robot - Xacro example for understanding.
  Xacro = XML Macros: reusable blocks, math, properties.
  Process with: xacro simple_diff_drive.urdf.xacro
  See: https://docs.ros.org/en/jazzy/Tutorials/Intermediate/URDF/Using-Xacro-to-Clean-Up-a-URDF-File.html
-->
<robot xmlns:xacro="http://www.ros.org/wiki/xacro" name="simple_diff_drive">

  <!-- Properties (constants) -->
  <xacro:property name="wheel_radius" value="0.05"/>
  <xacro:property name="wheel_separation" value="0.3"/>
  <xacro:property name="base_length" value="0.2"/>
  <xacro:property name="base_width" value="0.15"/>

  <!-- Base link -->
  <link name="base_footprint"/>

  <joint name="base_joint" type="fixed">
    <parent link="base_footprint"/>
    <child link="base_link"/>
    <origin xyz="0 0 ${wheel_radius}" rpy="0 0 0"/>
  </joint>

  <link name="base_link">
    <visual>
      <geometry>
        <box size="${base_length} ${base_width} 0.05"/>
      </geometry>
      <material name="blue">
        <color rgba="0 0 1 1"/>
      </material>
    </visual>
    <collision>
      <geometry>
        <box size="${base_length} ${base_width} 0.05"/>
      </geometry>
    </collision>
  </link>

  <!-- Left wheel -->
  <joint name="left_wheel_joint" type="continuous">
    <parent link="base_link"/>
    <child link="left_wheel"/>
    <origin xyz="0 ${wheel_separation * 0.5} 0" rpy="-1.5708 0 0"/>
    <axis xyz="0 0 1"/>
  </joint>

  <link name="left_wheel">
    <visual>
      <geometry>
        <cylinder radius="${wheel_radius}" length="0.02"/>
      </geometry>
      <material name="black"><color rgba="0.1 0.1 0.1 1"/></material>
    </visual>
  </link>

  <!-- Right wheel -->
  <joint name="right_wheel_joint" type="continuous">
    <parent link="base_link"/>
    <child link="right_wheel"/>
    <origin xyz="0 ${-wheel_separation * 0.5} 0" rpy="-1.5708 0 0"/>
    <axis xyz="0 0 1"/>
  </joint>

  <link name="right_wheel">
    <visual>
      <geometry>
        <cylinder radius="${wheel_radius}" length="0.02"/>
      </geometry>
      <material name="black"><color rgba="0.1 0.1 0.1 1"/></material>
    </visual>
  </link>

</robot>
